publilab_consulting@munbot:~/munbot-mcp$ docker logs -f complaints-mcp
Traceback (most recent call last):
  File "/usr/local/bin/gunicorn", line 8, in <module>
    sys.exit(run())
  File "/usr/local/lib/python3.9/site-packages/gunicorn/app/wsgiapp.py", line 67, in run
    WSGIApplication("%(prog)s [OPTIONS] [APP_MODULE]").run()
  File "/usr/local/lib/python3.9/site-packages/gunicorn/app/base.py", line 236, in run
    super().run()
  File "/usr/local/lib/python3.9/site-packages/gunicorn/app/base.py", line 72, in run
    Arbiter(self).run()
  File "/usr/local/lib/python3.9/site-packages/gunicorn/arbiter.py", line 58, in __init__
    self.setup(app)
  File "/usr/local/lib/python3.9/site-packages/gunicorn/arbiter.py", line 118, in setup
    self.app.wsgi()
  File "/usr/local/lib/python3.9/site-packages/gunicorn/app/base.py", line 67, in wsgi
    self.callable = self.load()
  File "/usr/local/lib/python3.9/site-packages/gunicorn/app/wsgiapp.py", line 58, in load
    return self.load_wsgiapp()
  File "/usr/local/lib/python3.9/site-packages/gunicorn/app/wsgiapp.py", line 48, in load_wsgiapp
    return util.import_app(self.app_uri)
  File "/usr/local/lib/python3.9/site-packages/gunicorn/util.py", line 371, in import_app
    mod = importlib.import_module(module)
  File "/usr/local/lib/python3.9/importlib/__init__.py", line 127, in import_module
    return _bootstrap._gcd_import(name[level:], package, level)
  File "<frozen importlib._bootstrap>", line 1030, in _gcd_import
  File "<frozen importlib._bootstrap>", line 1007, in _find_and_load
  File "<frozen importlib._bootstrap>", line 986, in _find_and_load_unlocked
  File "<frozen importlib._bootstrap>", line 680, in _load_unlocked
  File "<frozen importlib._bootstrap_external>", line 850, in exec_module
  File "<frozen importlib._bootstrap>", line 228, in _call_with_frames_removed
  File "/app/api.py", line 12, in <module>
    conn = psycopg2.connect(
  File "/usr/local/lib/python3.9/site-packages/psycopg2/__init__.py", line 122, in connect
    conn = _connect(dsn, connection_factory=connection_factory, **kwasync)
psycopg2.OperationalError: connection to server at "postgres" (172.18.0.3), port 5432 failed: FATAL:  database "munbot" does not exist

Traceback (most recent call last):
  File "/usr/local/bin/gunicorn", line 8, in <module>
    sys.exit(run())
  File "/usr/local/lib/python3.9/site-packages/gunicorn/app/wsgiapp.py", line 67, in run
    WSGIApplication("%(prog)s [OPTIONS] [APP_MODULE]").run()
  File "/usr/local/lib/python3.9/site-packages/gunicorn/app/base.py", line 236, in run
    super().run()
  File "/usr/local/lib/python3.9/site-packages/gunicorn/app/base.py", line 72, in run
    Arbiter(self).run()
  File "/usr/local/lib/python3.9/site-packages/gunicorn/arbiter.py", line 58, in __init__
    self.setup(app)
  File "/usr/local/lib/python3.9/site-packages/gunicorn/arbiter.py", line 118, in setup
    self.app.wsgi()
  File "/usr/local/lib/python3.9/site-packages/gunicorn/app/base.py", line 67, in wsgi
    self.callable = self.load()
  File "/usr/local/lib/python3.9/site-packages/gunicorn/app/wsgiapp.py", line 58, in load
    return self.load_wsgiapp()
  File "/usr/local/lib/python3.9/site-packages/gunicorn/app/wsgiapp.py", line 48, in load_wsgiapp
    return util.import_app(self.app_uri)
  File "/usr/local/lib/python3.9/site-packages/gunicorn/util.py", line 371, in import_app
    mod = importlib.import_module(module)
  File "/usr/local/lib/python3.9/importlib/__init__.py", line 127, in import_module
    return _bootstrap._gcd_import(name[level:], package, level)
  File "<frozen importlib._bootstrap>", line 1030, in _gcd_import
  File "<frozen importlib._bootstrap>", line 1007, in _find_and_load
  File "<frozen importlib._bootstrap>", line 986, in _find_and_load_unlocked
  File "<frozen importlib._bootstrap>", line 680, in _load_unlocked
  File "<frozen importlib._bootstrap_external>", line 850, in exec_module
  File "<frozen importlib._bootstrap>", line 228, in _call_with_frames_removed
  File "/app/api.py", line 12, in <module>
    conn = psycopg2.connect(
  File "/usr/local/lib/python3.9/site-packages/psycopg2/__init__.py", line 122, in connect
    conn = _connect(dsn, connection_factory=connection_factory, **kwasync)
psycopg2.OperationalError: connection to server at "postgres" (172.18.0.3), port 5432 failed: FATAL:  database "munbot" does not exist

Traceback (most recent call last):
  File "/usr/local/bin/gunicorn", line 8, in <module>
    sys.exit(run())
  File "/usr/local/lib/python3.9/site-packages/gunicorn/app/wsgiapp.py", line 67, in run
    WSGIApplication("%(prog)s [OPTIONS] [APP_MODULE]").run()
  File "/usr/local/lib/python3.9/site-packages/gunicorn/app/base.py", line 236, in run
    super().run()
  File "/usr/local/lib/python3.9/site-packages/gunicorn/app/base.py", line 72, in run
    Arbiter(self).run()
  File "/usr/local/lib/python3.9/site-packages/gunicorn/arbiter.py", line 58, in __init__
    self.setup(app)
  File "/usr/local/lib/python3.9/site-packages/gunicorn/arbiter.py", line 118, in setup
    self.app.wsgi()
  File "/usr/local/lib/python3.9/site-packages/gunicorn/app/base.py", line 67, in wsgi
    self.callable = self.load()
  File "/usr/local/lib/python3.9/site-packages/gunicorn/app/wsgiapp.py", line 58, in load
    return self.load_wsgiapp()
  File "/usr/local/lib/python3.9/site-packages/gunicorn/app/wsgiapp.py", line 48, in load_wsgiapp
    return util.import_app(self.app_uri)
  File "/usr/local/lib/python3.9/site-packages/gunicorn/util.py", line 371, in import_app
    mod = importlib.import_module(module)
  File "/usr/local/lib/python3.9/importlib/__init__.py", line 127, in import_module
    return _bootstrap._gcd_import(name[level:], package, level)
  File "<frozen importlib._bootstrap>", line 1030, in _gcd_import
  File "<frozen importlib._bootstrap>", line 1007, in _find_and_load
  File "<frozen importlib._bootstrap>", line 986, in _find_and_load_unlocked
  File "<frozen importlib._bootstrap>", line 680, in _load_unlocked
  File "<frozen importlib._bootstrap_external>", line 850, in exec_module
  File "<frozen importlib._bootstrap>", line 228, in _call_with_frames_removed
  File "/app/api.py", line 12, in <module>
    conn = psycopg2.connect(
  File "/usr/local/lib/python3.9/site-packages/psycopg2/__init__.py", line 122, in connect
    conn = _connect(dsn, connection_factory=connection_factory, **kwasync)
psycopg2.OperationalError: connection to server at "postgres" (172.18.0.3), port 5432 failed: FATAL:  database "munbot" does not exist

Traceback (most recent call last):
  File "/usr/local/bin/gunicorn", line 8, in <module>
    sys.exit(run())
  File "/usr/local/lib/python3.9/site-packages/gunicorn/app/wsgiapp.py", line 67, in run
    WSGIApplication("%(prog)s [OPTIONS] [APP_MODULE]").run()
  File "/usr/local/lib/python3.9/site-packages/gunicorn/app/base.py", line 236, in run
    super().run()
  File "/usr/local/lib/python3.9/site-packages/gunicorn/app/base.py", line 72, in run
    Arbiter(self).run()
  File "/usr/local/lib/python3.9/site-packages/gunicorn/arbiter.py", line 58, in __init__
    self.setup(app)
  File "/usr/local/lib/python3.9/site-packages/gunicorn/arbiter.py", line 118, in setup
    self.app.wsgi()
  File "/usr/local/lib/python3.9/site-packages/gunicorn/app/base.py", line 67, in wsgi
    self.callable = self.load()
  File "/usr/local/lib/python3.9/site-packages/gunicorn/app/wsgiapp.py", line 58, in load
    return self.load_wsgiapp()
  File "/usr/local/lib/python3.9/site-packages/gunicorn/app/wsgiapp.py", line 48, in load_wsgiapp
    return util.import_app(self.app_uri)
  File "/usr/local/lib/python3.9/site-packages/gunicorn/util.py", line 371, in import_app
    mod = importlib.import_module(module)
  File "/usr/local/lib/python3.9/importlib/__init__.py", line 127, in import_module
    return _bootstrap._gcd_import(name[level:], package, level)
  File "<frozen importlib._bootstrap>", line 1030, in _gcd_import
  File "<frozen importlib._bootstrap>", line 1007, in _find_and_load
  File "<frozen importlib._bootstrap>", line 986, in _find_and_load_unlocked
  File "<frozen importlib._bootstrap>", line 680, in _load_unlocked
  File "<frozen importlib._bootstrap_external>", line 850, in exec_module
  File "<frozen importlib._bootstrap>", line 228, in _call_with_frames_removed
  File "/app/api.py", line 12, in <module>
    conn = psycopg2.connect(
  File "/usr/local/lib/python3.9/site-packages/psycopg2/__init__.py", line 122, in connect
    conn = _connect(dsn, connection_factory=connection_factory, **kwasync)
psycopg2.OperationalError: connection to server at "postgres" (172.18.0.3), port 5432 failed: FATAL:  database "munbot" does not exist

Traceback (most recent call last):
  File "/usr/local/bin/gunicorn", line 8, in <module>
    sys.exit(run())
  File "/usr/local/lib/python3.9/site-packages/gunicorn/app/wsgiapp.py", line 67, in run
    WSGIApplication("%(prog)s [OPTIONS] [APP_MODULE]").run()
  File "/usr/local/lib/python3.9/site-packages/gunicorn/app/base.py", line 236, in run
    super().run()
  File "/usr/local/lib/python3.9/site-packages/gunicorn/app/base.py", line 72, in run
    Arbiter(self).run()
  File "/usr/local/lib/python3.9/site-packages/gunicorn/arbiter.py", line 58, in __init__
    self.setup(app)
  File "/usr/local/lib/python3.9/site-packages/gunicorn/arbiter.py", line 118, in setup
    self.app.wsgi()
  File "/usr/local/lib/python3.9/site-packages/gunicorn/app/base.py", line 67, in wsgi
    self.callable = self.load()
  File "/usr/local/lib/python3.9/site-packages/gunicorn/app/wsgiapp.py", line 58, in load
    return self.load_wsgiapp()
  File "/usr/local/lib/python3.9/site-packages/gunicorn/app/wsgiapp.py", line 48, in load_wsgiapp
    return util.import_app(self.app_uri)
  File "/usr/local/lib/python3.9/site-packages/gunicorn/util.py", line 371, in import_app
    mod = importlib.import_module(module)
  File "/usr/local/lib/python3.9/importlib/__init__.py", line 127, in import_module
    return _bootstrap._gcd_import(name[level:], package, level)
  File "<frozen importlib._bootstrap>", line 1030, in _gcd_import
  File "<frozen importlib._bootstrap>", line 1007, in _find_and_load
  File "<frozen importlib._bootstrap>", line 986, in _find_and_load_unlocked
  File "<frozen importlib._bootstrap>", line 680, in _load_unlocked
  File "<frozen importlib._bootstrap_external>", line 850, in exec_module
  File "<frozen importlib._bootstrap>", line 228, in _call_with_frames_removed
  File "/app/api.py", line 12, in <module>
    conn = psycopg2.connect(
  File "/usr/local/lib/python3.9/site-packages/psycopg2/__init__.py", line 122, in connect
    conn = _connect(dsn, connection_factory=connection_factory, **kwasync)
psycopg2.OperationalError: connection to server at "postgres" (172.18.0.3), port 5432 failed: FATAL:  database "munbot" does not exist

Traceback (most recent call last):
  File "/usr/local/bin/gunicorn", line 8, in <module>
    sys.exit(run())
  File "/usr/local/lib/python3.9/site-packages/gunicorn/app/wsgiapp.py", line 67, in run
    WSGIApplication("%(prog)s [OPTIONS] [APP_MODULE]").run()
  File "/usr/local/lib/python3.9/site-packages/gunicorn/app/base.py", line 236, in run
    super().run()
  File "/usr/local/lib/python3.9/site-packages/gunicorn/app/base.py", line 72, in run
    Arbiter(self).run()
  File "/usr/local/lib/python3.9/site-packages/gunicorn/arbiter.py", line 58, in __init__
    self.setup(app)
  File "/usr/local/lib/python3.9/site-packages/gunicorn/arbiter.py", line 118, in setup
    self.app.wsgi()
  File "/usr/local/lib/python3.9/site-packages/gunicorn/app/base.py", line 67, in wsgi
    self.callable = self.load()
  File "/usr/local/lib/python3.9/site-packages/gunicorn/app/wsgiapp.py", line 58, in load
    return self.load_wsgiapp()
  File "/usr/local/lib/python3.9/site-packages/gunicorn/app/wsgiapp.py", line 48, in load_wsgiapp
    return util.import_app(self.app_uri)
  File "/usr/local/lib/python3.9/site-packages/gunicorn/util.py", line 371, in import_app
    mod = importlib.import_module(module)
  File "/usr/local/lib/python3.9/importlib/__init__.py", line 127, in import_module
    return _bootstrap._gcd_import(name[level:], package, level)
  File "<frozen importlib._bootstrap>", line 1030, in _gcd_import
  File "<frozen importlib._bootstrap>", line 1007, in _find_and_load
  File "<frozen importlib._bootstrap>", line 986, in _find_and_load_unlocked
  File "<frozen importlib._bootstrap>", line 680, in _load_unlocked
  File "<frozen importlib._bootstrap_external>", line 850, in exec_module
  File "<frozen importlib._bootstrap>", line 228, in _call_with_frames_removed
  File "/app/api.py", line 12, in <module>
    conn = psycopg2.connect(
  File "/usr/local/lib/python3.9/site-packages/psycopg2/__init__.py", line 122, in connect
    conn = _connect(dsn, connection_factory=connection_factory, **kwasync)
psycopg2.OperationalError: connection to server at "postgres" (172.18.0.3), port 5432 failed: FATAL:  database "munbot" does not exist

Traceback (most recent call last):
  File "/usr/local/bin/gunicorn", line 8, in <module>
    sys.exit(run())
  File "/usr/local/lib/python3.9/site-packages/gunicorn/app/wsgiapp.py", line 67, in run
    WSGIApplication("%(prog)s [OPTIONS] [APP_MODULE]").run()
  File "/usr/local/lib/python3.9/site-packages/gunicorn/app/base.py", line 236, in run
    super().run()
  File "/usr/local/lib/python3.9/site-packages/gunicorn/app/base.py", line 72, in run
    Arbiter(self).run()
  File "/usr/local/lib/python3.9/site-packages/gunicorn/arbiter.py", line 58, in __init__
    self.setup(app)
  File "/usr/local/lib/python3.9/site-packages/gunicorn/arbiter.py", line 118, in setup
    self.app.wsgi()
  File "/usr/local/lib/python3.9/site-packages/gunicorn/app/base.py", line 67, in wsgi
    self.callable = self.load()
  File "/usr/local/lib/python3.9/site-packages/gunicorn/app/wsgiapp.py", line 58, in load
    return self.load_wsgiapp()
  File "/usr/local/lib/python3.9/site-packages/gunicorn/app/wsgiapp.py", line 48, in load_wsgiapp
    return util.import_app(self.app_uri)
  File "/usr/local/lib/python3.9/site-packages/gunicorn/util.py", line 371, in import_app
    mod = importlib.import_module(module)
  File "/usr/local/lib/python3.9/importlib/__init__.py", line 127, in import_module
    return _bootstrap._gcd_import(name[level:], package, level)
  File "<frozen importlib._bootstrap>", line 1030, in _gcd_import
  File "<frozen importlib._bootstrap>", line 1007, in _find_and_load
  File "<frozen importlib._bootstrap>", line 986, in _find_and_load_unlocked
  File "<frozen importlib._bootstrap>", line 680, in _load_unlocked
  File "<frozen importlib._bootstrap_external>", line 850, in exec_module
  File "<frozen importlib._bootstrap>", line 228, in _call_with_frames_removed
  File "/app/api.py", line 12, in <module>
    conn = psycopg2.connect(
  File "/usr/local/lib/python3.9/site-packages/psycopg2/__init__.py", line 122, in connect
    conn = _connect(dsn, connection_factory=connection_factory, **kwasync)
psycopg2.OperationalError: connection to server at "postgres" (172.18.0.3), port 5432 failed: FATAL:  database "munbot" does not exist

Traceback (most recent call last):
  File "/usr/local/bin/gunicorn", line 8, in <module>
    sys.exit(run())
  File "/usr/local/lib/python3.9/site-packages/gunicorn/app/wsgiapp.py", line 67, in run
    WSGIApplication("%(prog)s [OPTIONS] [APP_MODULE]").run()
  File "/usr/local/lib/python3.9/site-packages/gunicorn/app/base.py", line 236, in run
    super().run()
  File "/usr/local/lib/python3.9/site-packages/gunicorn/app/base.py", line 72, in run
    Arbiter(self).run()
  File "/usr/local/lib/python3.9/site-packages/gunicorn/arbiter.py", line 58, in __init__
    self.setup(app)
  File "/usr/local/lib/python3.9/site-packages/gunicorn/arbiter.py", line 118, in setup
    self.app.wsgi()
  File "/usr/local/lib/python3.9/site-packages/gunicorn/app/base.py", line 67, in wsgi
    self.callable = self.load()
  File "/usr/local/lib/python3.9/site-packages/gunicorn/app/wsgiapp.py", line 58, in load
    return self.load_wsgiapp()
  File "/usr/local/lib/python3.9/site-packages/gunicorn/app/wsgiapp.py", line 48, in load_wsgiapp
    return util.import_app(self.app_uri)
  File "/usr/local/lib/python3.9/site-packages/gunicorn/util.py", line 371, in import_app
    mod = importlib.import_module(module)
  File "/usr/local/lib/python3.9/importlib/__init__.py", line 127, in import_module
    return _bootstrap._gcd_import(name[level:], package, level)
  File "<frozen importlib._bootstrap>", line 1030, in _gcd_import
  File "<frozen importlib._bootstrap>", line 1007, in _find_and_load
  File "<frozen importlib._bootstrap>", line 986, in _find_and_load_unlocked
  File "<frozen importlib._bootstrap>", line 680, in _load_unlocked
  File "<frozen importlib._bootstrap_external>", line 850, in exec_module
  File "<frozen importlib._bootstrap>", line 228, in _call_with_frames_removed
  File "/app/api.py", line 12, in <module>
    conn = psycopg2.connect(
  File "/usr/local/lib/python3.9/site-packages/psycopg2/__init__.py", line 122, in connect
    conn = _connect(dsn, connection_factory=connection_factory, **kwasync)
psycopg2.OperationalError: connection to server at "postgres" (172.18.0.3), port 5432 failed: FATAL:  database "munbot" does not exist

Traceback (most recent call last):
  File "/usr/local/bin/gunicorn", line 8, in <module>
    sys.exit(run())
  File "/usr/local/lib/python3.9/site-packages/gunicorn/app/wsgiapp.py", line 67, in run
    WSGIApplication("%(prog)s [OPTIONS] [APP_MODULE]").run()
  File "/usr/local/lib/python3.9/site-packages/gunicorn/app/base.py", line 236, in run
    super().run()
  File "/usr/local/lib/python3.9/site-packages/gunicorn/app/base.py", line 72, in run
    Arbiter(self).run()
  File "/usr/local/lib/python3.9/site-packages/gunicorn/arbiter.py", line 58, in __init__
    self.setup(app)
  File "/usr/local/lib/python3.9/site-packages/gunicorn/arbiter.py", line 118, in setup
    self.app.wsgi()
  File "/usr/local/lib/python3.9/site-packages/gunicorn/app/base.py", line 67, in wsgi
    self.callable = self.load()
  File "/usr/local/lib/python3.9/site-packages/gunicorn/app/wsgiapp.py", line 58, in load
    return self.load_wsgiapp()
  File "/usr/local/lib/python3.9/site-packages/gunicorn/app/wsgiapp.py", line 48, in load_wsgiapp
    return util.import_app(self.app_uri)
  File "/usr/local/lib/python3.9/site-packages/gunicorn/util.py", line 371, in import_app
    mod = importlib.import_module(module)
  File "/usr/local/lib/python3.9/importlib/__init__.py", line 127, in import_module
    return _bootstrap._gcd_import(name[level:], package, level)
  File "<frozen importlib._bootstrap>", line 1030, in _gcd_import
  File "<frozen importlib._bootstrap>", line 1007, in _find_and_load
  File "<frozen importlib._bootstrap>", line 986, in _find_and_load_unlocked
  File "<frozen importlib._bootstrap>", line 680, in _load_unlocked
  File "<frozen importlib._bootstrap_external>", line 850, in exec_module
  File "<frozen importlib._bootstrap>", line 228, in _call_with_frames_removed
  File "/app/api.py", line 12, in <module>
    conn = psycopg2.connect(
  File "/usr/local/lib/python3.9/site-packages/psycopg2/__init__.py", line 122, in connect
    conn = _connect(dsn, connection_factory=connection_factory, **kwasync)
psycopg2.OperationalError: connection to server at "postgres" (172.18.0.3), port 5432 failed: FATAL:  database "munbot" does not exist

Traceback (most recent call last):
  File "/usr/local/bin/gunicorn", line 8, in <module>
    sys.exit(run())
  File "/usr/local/lib/python3.9/site-packages/gunicorn/app/wsgiapp.py", line 67, in run
    WSGIApplication("%(prog)s [OPTIONS] [APP_MODULE]").run()
  File "/usr/local/lib/python3.9/site-packages/gunicorn/app/base.py", line 236, in run
    super().run()
  File "/usr/local/lib/python3.9/site-packages/gunicorn/app/base.py", line 72, in run
    Arbiter(self).run()
  File "/usr/local/lib/python3.9/site-packages/gunicorn/arbiter.py", line 58, in __init__
    self.setup(app)
  File "/usr/local/lib/python3.9/site-packages/gunicorn/arbiter.py", line 118, in setup
    self.app.wsgi()
  File "/usr/local/lib/python3.9/site-packages/gunicorn/app/base.py", line 67, in wsgi
    self.callable = self.load()
  File "/usr/local/lib/python3.9/site-packages/gunicorn/app/wsgiapp.py", line 58, in load
    return self.load_wsgiapp()
  File "/usr/local/lib/python3.9/site-packages/gunicorn/app/wsgiapp.py", line 48, in load_wsgiapp
    return util.import_app(self.app_uri)
  File "/usr/local/lib/python3.9/site-packages/gunicorn/util.py", line 371, in import_app
    mod = importlib.import_module(module)
  File "/usr/local/lib/python3.9/importlib/__init__.py", line 127, in import_module
    return _bootstrap._gcd_import(name[level:], package, level)
  File "<frozen importlib._bootstrap>", line 1030, in _gcd_import
  File "<frozen importlib._bootstrap>", line 1007, in _find_and_load
  File "<frozen importlib._bootstrap>", line 986, in _find_and_load_unlocked
  File "<frozen importlib._bootstrap>", line 680, in _load_unlocked
  File "<frozen importlib._bootstrap_external>", line 850, in exec_module
  File "<frozen importlib._bootstrap>", line 228, in _call_with_frames_removed
  File "/app/api.py", line 12, in <module>
    conn = psycopg2.connect(
  File "/usr/local/lib/python3.9/site-packages/psycopg2/__init__.py", line 122, in connect
    conn = _connect(dsn, connection_factory=connection_factory, **kwasync)
psycopg2.OperationalError: connection to server at "postgres" (172.18.0.3), port 5432 failed: FATAL:  database "munbot" does not exist

Traceback (most recent call last):
  File "/usr/local/bin/gunicorn", line 8, in <module>
    sys.exit(run())
  File "/usr/local/lib/python3.9/site-packages/gunicorn/app/wsgiapp.py", line 67, in run
    WSGIApplication("%(prog)s [OPTIONS] [APP_MODULE]").run()
  File "/usr/local/lib/python3.9/site-packages/gunicorn/app/base.py", line 236, in run
    super().run()
  File "/usr/local/lib/python3.9/site-packages/gunicorn/app/base.py", line 72, in run
    Arbiter(self).run()
  File "/usr/local/lib/python3.9/site-packages/gunicorn/arbiter.py", line 58, in __init__
    self.setup(app)
  File "/usr/local/lib/python3.9/site-packages/gunicorn/arbiter.py", line 118, in setup
    self.app.wsgi()
  File "/usr/local/lib/python3.9/site-packages/gunicorn/app/base.py", line 67, in wsgi
    self.callable = self.load()
  File "/usr/local/lib/python3.9/site-packages/gunicorn/app/wsgiapp.py", line 58, in load
    return self.load_wsgiapp()
  File "/usr/local/lib/python3.9/site-packages/gunicorn/app/wsgiapp.py", line 48, in load_wsgiapp
    return util.import_app(self.app_uri)
  File "/usr/local/lib/python3.9/site-packages/gunicorn/util.py", line 371, in import_app
    mod = importlib.import_module(module)
  File "/usr/local/lib/python3.9/importlib/__init__.py", line 127, in import_module
    return _bootstrap._gcd_import(name[level:], package, level)
  File "<frozen importlib._bootstrap>", line 1030, in _gcd_import
  File "<frozen importlib._bootstrap>", line 1007, in _find_and_load
  File "<frozen importlib._bootstrap>", line 986, in _find_and_load_unlocked
  File "<frozen importlib._bootstrap>", line 680, in _load_unlocked
  File "<frozen importlib._bootstrap_external>", line 850, in exec_module
  File "<frozen importlib._bootstrap>", line 228, in _call_with_frames_removed
  File "/app/api.py", line 12, in <module>
    conn = psycopg2.connect(
  File "/usr/local/lib/python3.9/site-packages/psycopg2/__init__.py", line 122, in connect
    conn = _connect(dsn, connection_factory=connection_factory, **kwasync)
psycopg2.OperationalError: connection to server at "postgres" (172.18.0.3), port 5432 failed: FATAL:  database "munbot" does not exist

Traceback (most recent call last):
  File "/usr/local/bin/gunicorn", line 8, in <module>
    sys.exit(run())
  File "/usr/local/lib/python3.9/site-packages/gunicorn/app/wsgiapp.py", line 67, in run
    WSGIApplication("%(prog)s [OPTIONS] [APP_MODULE]").run()
  File "/usr/local/lib/python3.9/site-packages/gunicorn/app/base.py", line 236, in run
    super().run()
  File "/usr/local/lib/python3.9/site-packages/gunicorn/app/base.py", line 72, in run
    Arbiter(self).run()
  File "/usr/local/lib/python3.9/site-packages/gunicorn/arbiter.py", line 58, in __init__
    self.setup(app)
  File "/usr/local/lib/python3.9/site-packages/gunicorn/arbiter.py", line 118, in setup
    self.app.wsgi()
  File "/usr/local/lib/python3.9/site-packages/gunicorn/app/base.py", line 67, in wsgi
    self.callable = self.load()
  File "/usr/local/lib/python3.9/site-packages/gunicorn/app/wsgiapp.py", line 58, in load
    return self.load_wsgiapp()
  File "/usr/local/lib/python3.9/site-packages/gunicorn/app/wsgiapp.py", line 48, in load_wsgiapp
    return util.import_app(self.app_uri)
  File "/usr/local/lib/python3.9/site-packages/gunicorn/util.py", line 371, in import_app
    mod = importlib.import_module(module)
  File "/usr/local/lib/python3.9/importlib/__init__.py", line 127, in import_module
    return _bootstrap._gcd_import(name[level:], package, level)
  File "<frozen importlib._bootstrap>", line 1030, in _gcd_import
  File "<frozen importlib._bootstrap>", line 1007, in _find_and_load
  File "<frozen importlib._bootstrap>", line 986, in _find_and_load_unlocked
  File "<frozen importlib._bootstrap>", line 680, in _load_unlocked
  File "<frozen importlib._bootstrap_external>", line 850, in exec_module
  File "<frozen importlib._bootstrap>", line 228, in _call_with_frames_removed
  File "/app/api.py", line 12, in <module>
    conn = psycopg2.connect(
  File "/usr/local/lib/python3.9/site-packages/psycopg2/__init__.py", line 122, in connect
    conn = _connect(dsn, connection_factory=connection_factory, **kwasync)
psycopg2.OperationalError: connection to server at "postgres" (172.18.0.3), port 5432 failed: FATAL:  database "munbot" does not exist

Traceback (most recent call last):
  File "/usr/local/bin/gunicorn", line 8, in <module>
    sys.exit(run())
  File "/usr/local/lib/python3.9/site-packages/gunicorn/app/wsgiapp.py", line 67, in run
    WSGIApplication("%(prog)s [OPTIONS] [APP_MODULE]").run()
  File "/usr/local/lib/python3.9/site-packages/gunicorn/app/base.py", line 236, in run
    super().run()
  File "/usr/local/lib/python3.9/site-packages/gunicorn/app/base.py", line 72, in run
    Arbiter(self).run()
  File "/usr/local/lib/python3.9/site-packages/gunicorn/arbiter.py", line 58, in __init__
    self.setup(app)
  File "/usr/local/lib/python3.9/site-packages/gunicorn/arbiter.py", line 118, in setup
    self.app.wsgi()
  File "/usr/local/lib/python3.9/site-packages/gunicorn/app/base.py", line 67, in wsgi
    self.callable = self.load()
  File "/usr/local/lib/python3.9/site-packages/gunicorn/app/wsgiapp.py", line 58, in load
    return self.load_wsgiapp()
  File "/usr/local/lib/python3.9/site-packages/gunicorn/app/wsgiapp.py", line 48, in load_wsgiapp
    return util.import_app(self.app_uri)
  File "/usr/local/lib/python3.9/site-packages/gunicorn/util.py", line 371, in import_app
    mod = importlib.import_module(module)
  File "/usr/local/lib/python3.9/importlib/__init__.py", line 127, in import_module
    return _bootstrap._gcd_import(name[level:], package, level)
  File "<frozen importlib._bootstrap>", line 1030, in _gcd_import
  File "<frozen importlib._bootstrap>", line 1007, in _find_and_load
  File "<frozen importlib._bootstrap>", line 986, in _find_and_load_unlocked
  File "<frozen importlib._bootstrap>", line 680, in _load_unlocked
  File "<frozen importlib._bootstrap_external>", line 850, in exec_module
  File "<frozen importlib._bootstrap>", line 228, in _call_with_frames_removed
  File "/app/api.py", line 12, in <module>
    conn = psycopg2.connect(
  File "/usr/local/lib/python3.9/site-packages/psycopg2/__init__.py", line 122, in connect
    conn = _connect(dsn, connection_factory=connection_factory, **kwasync)
psycopg2.OperationalError: connection to server at "postgres" (172.18.0.3), port 5432 failed: FATAL:  database "munbot" does not exist

Traceback (most recent call last):
  File "/usr/local/bin/gunicorn", line 8, in <module>
    sys.exit(run())
  File "/usr/local/lib/python3.9/site-packages/gunicorn/app/wsgiapp.py", line 67, in run
    WSGIApplication("%(prog)s [OPTIONS] [APP_MODULE]").run()
  File "/usr/local/lib/python3.9/site-packages/gunicorn/app/base.py", line 236, in run
    super().run()
  File "/usr/local/lib/python3.9/site-packages/gunicorn/app/base.py", line 72, in run
    Arbiter(self).run()
  File "/usr/local/lib/python3.9/site-packages/gunicorn/arbiter.py", line 58, in __init__
    self.setup(app)
  File "/usr/local/lib/python3.9/site-packages/gunicorn/arbiter.py", line 118, in setup
    self.app.wsgi()
  File "/usr/local/lib/python3.9/site-packages/gunicorn/app/base.py", line 67, in wsgi
    self.callable = self.load()
  File "/usr/local/lib/python3.9/site-packages/gunicorn/app/wsgiapp.py", line 58, in load
    return self.load_wsgiapp()
  File "/usr/local/lib/python3.9/site-packages/gunicorn/app/wsgiapp.py", line 48, in load_wsgiapp
    return util.import_app(self.app_uri)
  File "/usr/local/lib/python3.9/site-packages/gunicorn/util.py", line 371, in import_app
    mod = importlib.import_module(module)
  File "/usr/local/lib/python3.9/importlib/__init__.py", line 127, in import_module
    return _bootstrap._gcd_import(name[level:], package, level)
  File "<frozen importlib._bootstrap>", line 1030, in _gcd_import
  File "<frozen importlib._bootstrap>", line 1007, in _find_and_load
  File "<frozen importlib._bootstrap>", line 986, in _find_and_load_unlocked
  File "<frozen importlib._bootstrap>", line 680, in _load_unlocked
  File "<frozen importlib._bootstrap_external>", line 850, in exec_module
  File "<frozen importlib._bootstrap>", line 228, in _call_with_frames_removed
  File "/app/api.py", line 12, in <module>
    conn = psycopg2.connect(
  File "/usr/local/lib/python3.9/site-packages/psycopg2/__init__.py", line 122, in connect
    conn = _connect(dsn, connection_factory=connection_factory, **kwasync)
psycopg2.OperationalError: connection to server at "postgres" (172.18.0.3), port 5432 failed: FATAL:  database "munbot" does not exist

Traceback (most recent call last):
  File "/usr/local/bin/gunicorn", line 8, in <module>
    sys.exit(run())
  File "/usr/local/lib/python3.9/site-packages/gunicorn/app/wsgiapp.py", line 67, in run
    WSGIApplication("%(prog)s [OPTIONS] [APP_MODULE]").run()
  File "/usr/local/lib/python3.9/site-packages/gunicorn/app/base.py", line 236, in run
    super().run()
  File "/usr/local/lib/python3.9/site-packages/gunicorn/app/base.py", line 72, in run
    Arbiter(self).run()
  File "/usr/local/lib/python3.9/site-packages/gunicorn/arbiter.py", line 58, in __init__
    self.setup(app)
  File "/usr/local/lib/python3.9/site-packages/gunicorn/arbiter.py", line 118, in setup
    self.app.wsgi()
  File "/usr/local/lib/python3.9/site-packages/gunicorn/app/base.py", line 67, in wsgi
    self.callable = self.load()
  File "/usr/local/lib/python3.9/site-packages/gunicorn/app/wsgiapp.py", line 58, in load
    return self.load_wsgiapp()
  File "/usr/local/lib/python3.9/site-packages/gunicorn/app/wsgiapp.py", line 48, in load_wsgiapp
    return util.import_app(self.app_uri)
  File "/usr/local/lib/python3.9/site-packages/gunicorn/util.py", line 371, in import_app
    mod = importlib.import_module(module)
  File "/usr/local/lib/python3.9/importlib/__init__.py", line 127, in import_module
    return _bootstrap._gcd_import(name[level:], package, level)
  File "<frozen importlib._bootstrap>", line 1030, in _gcd_import
  File "<frozen importlib._bootstrap>", line 1007, in _find_and_load
  File "<frozen importlib._bootstrap>", line 986, in _find_and_load_unlocked
  File "<frozen importlib._bootstrap>", line 680, in _load_unlocked
  File "<frozen importlib._bootstrap_external>", line 850, in exec_module
  File "<frozen importlib._bootstrap>", line 228, in _call_with_frames_removed
  File "/app/api.py", line 12, in <module>
    conn = psycopg2.connect(
  File "/usr/local/lib/python3.9/site-packages/psycopg2/__init__.py", line 122, in connect
    conn = _connect(dsn, connection_factory=connection_factory, **kwasync)
psycopg2.OperationalError: connection to server at "postgres" (172.18.0.3), port 5432 failed: FATAL:  database "munbot" does not exist